Workbook

Sheet Outubro
C1: FLUXO DE CAIXA OUTUBRO/2025
A2: STATUS | B2: DATA | C2: TIPO | D2: HISTÓRICO | E2: DESPESA | F2: RECEITA | G2: SALDO
C3: SALDO INICIAL | G3: 13424.55
A4: OK | B4: 45933 | C4: RECEBIMENTO | D4: TRANSFERENCIA SHOPEE | F4: 1776.64 | G4: =G3+F4-E4 -> 15201.19
A5: OK | B5: 45933 | C5: FORNECEDORES | D5: ETIQUETA TÉRMICA | E5: 139.94 | G5: =G4+F5-E5 -> 15061.25
A6: OK | B6: 45933 | C6: SHOPEE ADS | D6: SHOPEE ADS | E6: 20 | G6: =G5+F6-E6 -> 15041.25
A7: OK | B7: 45935 | C7: MATÉRIA PRIMA | D7: PAGAMENTO PEDIDO 25/08 - TUCK KIDS PARC 1/3 | E7: 1417.5 | G7: =G6+F7-E7 -> 13623.75
A8: OK | B8: 45935 | C8: MATÉRIA PRIMA | D8: PAGAMENTO PEDIDO 05/09 - TUCK KIDS PARC 1/3 | E8: 531.66 | G8: =G7+F8-E8 -> 13092.09
A9: OK | B9: 45937 | C9: RECEBIMENTO | D9: TRANSFERENCIA SHOPEE | F9: 972.16 | G9: =G8+F9-E9 -> 14064.25
A10: OK | B10: 45937 | C10: FORNECEDORES | D10: CONTABILIDADE | E10: 350 | G10: =G9+F10-E10 -> 13714.25
A11: OK | B11: 45937 | C11: FOLHA | D11: PAGAMENTO SALÁRIO BRUNA | E11: 1000 | G11: =G10+F11-E11 -> 12714.25
A12: OK | B12: 45938 | C12: SHOPEE ADS | D12: SHOPEE ADS | E12: 50 | G12: =G11+F12-E12 -> 12664.25
A13: OK | B13: 45938 | C13: RECEBIMENTO | D13: TRANSFERENCIA SHOPEE | F13: 756.88 | G13: =G12+F13-E13 -> 13421.13
A14: OK | B14: 45939 | C14: RECEBIMENTO | D14: TRANSFERENCIA SHOPEE | F14: 612.82 | G14: =G13+F14-E14 -> 14033.95
A15: OK | B15: 45940 | C15: MATÉRIA PRIMA | D15: PAGAMENTO PEDIDO 10/10 - KAPPES PARC 1/4 | E15: 2703.42 | G15: =G14+F15-E15 -> 11330.53
A16: OK | B16: 45940 | C16: APORTE | D16: APORTE JACKSON 2.246,82 | F16: 2246.82 | G16: =G15+F16-E16 -> 13577.35
A17: OK | B17: 45940 | C17: MATÉRIA PRIMA | D17: PAGAMENTO PEDIDO 16/09 - KAPPES | E17: 2246.82 | G17: =G16+F17-E17 -> 11330.53
A18: OK | B18: 45940 | C18: RECEBIMENTO | D18: TRANSFERENCIA MERCADO LIVRE | F18: 788.16 | G18: =G17+F18-E18 -> 12118.69
A19: OK | B19: 45943 | C19: RECEBIMENTO | D19: TRANSFERENCIA SHOPEE | F19: 638.62 | G19: =G18+F19-E19 -> 12757.31
A20: OK | B20: 45943 | C20: CARTAO | D20: CURSOS E TREINAMENTO PARC 1/12 | E20: 64.42 | G20: =G19+F20-E20 -> 12692.89
A21: OK | B21: 45945 | C21: RECEBIMENTO | D21: TRANSFERENCIA SHOPEE | F21: 2094.61 | G21: =G20+F21-E21 -> 14787.5
A22: OK | B22: 45947 | C22: RECEBIMENTO | D22: TRANSFERENCIA SHOPEE | F22: 852.54 | G22: =G21+F22-E22 -> 15640.04
A23: OK | B23: 45947 | C23: SHOPEE ADS | D23: SHOPEE ADS | E23: 50 | G23: =G22+F23-E23 -> 15590.04
A24: OK | B24: 45948 | C24: SHOPEE ADS | D24: SHOPEE ADS | E24: 25 | G24: =G23+F24-E24 -> 15565.04
A25: OK | B25: 45948 | C25: RECEBIMENTO | D25: TRANSFERENCIA SHOPEE | F25: 1111.47 | G25: =G24+F25-E25 -> 16676.51
A26: OK | B26: 45950 | C26: RECEBIMENTO | D26: TRANSFERENCIA SHOPEE | F26: 849.11 | G26: =G25+F26-E26 -> 17525.62
A27: OK | B27: 45950 | C27: IMPOSTO | D27: IMPOSTO PROJETADO DE SETEMBRO | E27: 629.06 | G27: =G26+F27-E27 -> 16896.56
A28: OK | B28: 45950 | C28: RECEBIMENTO | D28: VENDA POR FORA | F28: 89.7 | G28: =G27+F28-E28 -> 16986.26
A29: OK | B29: 45951 | C29: RECEBIMENTO | D29: TRANSFERENCIA SHOPEE | F29: 638.83 | G29: =G28+F29-E29 -> 17625.09
A30: OK | B30: 45952 | C30: MATÉRIA PRIMA | D30: PAGAMENTO PEDIDO 22/07 - TUCK KIDS 3/3 | E30: 1604.17 | G30: =G29+F30-E30 -> 16020.92
A31: OK | B31: 45952 | C31: MATÉRIA PRIMA | D31: PAGAMENTO PEDIDO PROG 09/10 - TUCK KIDS 1/3 | E31: 11100 | G31: =G30+F31-E31 -> 4920.92
A32: OK | B32: 45953 | C32: RECEBIMENTO | D32: VENDA POR FORA | F32: 59.9 | G32: =G31+F32-E32 -> 4980.82
A33: OK | B33: 45953 | C33: RECEBIMENTO | D33: RENDIMENTO CAIXINHA | F33: 86.02 | G33: =G32+F33-E33 -> 5066.84
A34: OK | B34: 45953 | C34: RECEBIMENTO | D34: TRANSFERENCIA SHOPEE | F34: 1141.02 | G34: =G33+F34-E34 -> 6207.86
A35: OK | B35: 45958 | C35: RECEBIMENTO | D35: TRANSFERENCIA SHOPEE | F35: 1840.04 | G35: =G34+F35-E35 -> 8047.9
A36: OK | B36: 45959 | C36: RECEBIMENTO | D36: TRANSFERENCIA SHOPEE | F36: 557.79 | G36: =G35+F36-E36 -> 8605.69
A37: OK | B37: 45959 | C37: MATÉRIA PRIMA | D37: PAGAMENTO PEDIDO 22/07 - TUCK KIDS 1/3 | E37: 875 | G37: =G36+F37-E37 -> 7730.69
A38: OK | B38: 45961 | C38: SHOPEE ADS | D38: SHOPEE ADS | E38: 100 | G38: =G37+F38-E38 -> 7630.69
A39: OK | B39: 45961 | C39: RECEBIMENTO | D39: TRANSFERENCIA MERCADO LIVRE | F39: 120.61 | G39: =G38+F39-E39 -> 7751.3
E40: =SUM(E4:E38) -> 22906.99 | F40: =SUM(F4:F37) -> 17113.13 | G40: =G39 -> 7751.3

Sheet Novembro
A1: FLUXO DE CAIXA NOVEMBRO/2025
A2: STATUS | B2: DATA | C2: TIPO | D2: HISTÓRICO | E2: DESPESA | F2: RECEITA | G2: SALDO
B3: SALDO INICIAL | G3: =Outubro!G40 -> 7751.3
A4: OK | B4: 45962 | C4: RECEBIMENTO | D4: TRANSFERENCIA SHOPEE | F4: 988.54 | G4: =G3+F4-E4 -> 8739.84
A5: OK | B5: 45963 | C5: RECEBIMENTO | D5: TRANSFERENCIA MERCADO LIVRE | F5: 348.52 | G5: =G4+F5-E5 -> 9088.36
A6: OK | B6: 45964 | C6: RECEBIMENTO | D6: TRANSFERENCIA SHOPEE | F6: 833.32 | G6: =G5+F6-E6 -> 9921.68
A7: OK | B7: 45964 | C7: RECEBIMENTO | D7: TRANSFERENCIA SHOPEE | F7: 219.88 | G7: =G6+F7-E7 -> 10141.56
A8: OK | B8: 45964 | C8: SHOPEE ADS | D8: SHOPEE ADS | E8: 100 | G8: =G7+F8-E8 -> 10041.56
A9: OK | B9: 45966 | C9: RECEBIMENTO | D9: TRANSFERENCIA SHOPEE | F9: 1000 | G9: =G8+F9-E9 -> 11041.56
A10: Ok | B10: 45966 | C10: MATÉRIA PRIMA | D10: PAGAMENTO PEDIDO 25/08 - TUCK KIDS PARC 2/3 | E10: 1417.5 | G10: =G9+F10-E10 -> 9624.06
A11: OK | B11: 45966 | C11: MATÉRIA PRIMA | D11: PAGAMENTO PEDIDO 05/09 - TUCK KIDS PARC 2/3 | E11: 531.66 | G11: =G10+F11-E11 -> 9092.4
A12: OK | B12: 45968 | C12: RECEBIMENTO | D12: TRANSFERENCIA SHOPEE | F12: 1200 | G12: =G11+F12-E12 -> 10292.4
A13: OK | B13: 45968 | C13: FORNECEDORES | D13: UPSELLER | E13: 149 | G13: =G12+F13-E13 -> 10143.4
A14: OK | B14: 45968 | C14: MATÉRIA PRIMA | D14: PAGAMENTO PEDIDO 07/10 - TUCK KIDS PARC 1/3 | E14: 801.66 | G14: =G13+F14-E14 -> 9341.74
A15: OK | B15: 45968 | C15: FORNECEDORES | D15: CONTABILIDADE | E15: 350 | G15: =G14+F15-E15 -> 8991.74
A16: OK | B16: 45968 | C16: FOLHA | D16: PAGAMENTO SALÁRIO BRUNA | E16: 1000 | G16: =G15+F16-E16 -> 7991.74
A17: OK | B17: 45968 | C17: RECEBIMENTO | D17: TRANSFERENCIA MERCADO LIVRE | F17: 199.47 | G17: =G16+F17-E17 -> 8191.21
A18: OK | B18: 45969 | C18: RECEBIMENTO | D18: TRANSFERENCIA SHOPEE | F18: 1200 | G18: =G17+F18-E18 -> 9391.21
A19: OK | B19: 45969 | C19: RECEBIMENTO | D19: TRANSFERENCIA SHOPEE | F19: 1400 | G19: =G18+F19-E19 -> 10791.21
A20: OK | B20: 45969 | C20: RECEBIMENTO | D20: TRANSFERENCIA SHOPEE | F20: 1200 | G20: =G19+F20-E20 -> 11991.21
A21: OK | B21: 45971 | C21: RECEBIMENTO | D21: TRANSFERENCIA SHOPEE | F21: 1200 | G21: =G20+F21-E21 -> 13191.21
A22: OK | B22: 45970 | C22: MATÉRIA PRIMA | D22: PAGAMENTO PEDIDO 10/10 - KAPPES PARC 2/4 | E22: 901.14 | G22: =G21+F22-E22 -> 12290.07
A23: OK | B23: 45971 | C23: APORTE | D23: APORTE JACKSON 2.246,82 | F23: 2246.82 | G23: =G22+F23-E23 -> 14536.89
A24: OK | B24: 45971 | C24: MATÉRIA PRIMA | D24: PAGAMENTO PEDIDO 16/09 - KAPPES | E24: 2246.82 | G24: =G23+F24-E24 -> 12290.07
A25: OK | B25: 45971 | C25: RECEBIMENTO | D25: TRANSFERENCIA MERCADO LIVRE | F25: 625.12 | G25: =G24+F25-E25 -> 12915.19
A26: OK | B26: 45972 | C26: RECEBIMENTO | D26: TRANSFERENCIA SHOPEE | F26: 1300 | G26: =G25+F26-E26 -> 14215.19
A27: OK | B27: 45972 | C27: FORNECEDORES | D27: ETIQUETA IMPRESSORA TÉRMICA | E27: 141.93 | G27: =G26+F27-E27 -> 14073.26
A28: OK | B28: 45974 | C28: CARTAO | D28: CURSOS E TREINAMENTO PARC 2/12 | E28: 66.96 | G28: =G27+F28-E28 -> 14006.3
A29: OK | B29: 45973 | C29: RECEBIMENTO | D29: TRANSFERENCIA MERCADO LIVRE | F29: 430.52 | G29: =G28+F29-E29 -> 14436.82
A30: OK | B30: 45974 | C30: RECEBIMENTO | D30: TRANSFERENCIA SHOPEE | F30: 1800 | G30: =G29+F30-E30 -> 16236.82
A31: OK | B31: 45975 | C31: RECEBIMENTO | D31: TRANSFERENCIA SHOPEE | F31: 1200 | G31: =G30+F31-E31 -> 17436.82
A32: OK | B32: 45976 | C32: MATÉRIA PRIMA | D32: PAGAMENTO PEDIDO 15/10 - TUCK KIDS PARC 1/3 | E32: 1195.83 | G32: =G31+F32-E32 -> 16240.99
A33: OK | B33: 45976 | C33: RECEBIMENTO | D33: TRANSFERENCIA MERCADO LIVRE | F33: 337.03 | G33: =G32+F33-E33 -> 16578.02
A34: OK | B34: 45977 | C34: RECEBIMENTO | D34: TRANSFERENCIA SHOPEE | F34: 1200 | G34: =G33+F34-E34 -> 17778.02
A35: OK | B35: 45977 | C35: RECEBIMENTO | D35: TRANSFERENCIA MERCADO LIVRE | F35: 526.81 | G35: =G34+F35-E35 -> 18304.83
A36: OK | B36: 45978 | C36: RECEBIMENTO | D36: TRANSFERENCIA SHOPEE | F36: 1600 | G36: =G35+F36-E36 -> 19904.83
A37: OK | B37: 45978 | C37: RECEBIMENTO | D37: TRANSFERENCIA MERCADO LIVRE | F37: 252.61 | G37: =G36+F37-E37 -> 20157.44
A38: OK | B38: 45979 | C38: MATÉRIA PRIMA | D38: PAGAMENTO PEDIDO 03/10 - TUCK KIDS PARC 1/3 | E38: 595.38 | G38: =G37+F38-E38 -> 19562.06
A39: OK | B39: 45979 | C39: RECEBIMENTO | D39: TRANSFERENCIA SHOPEE | F39: 1100 | G39: =G38+F39-E39 -> 20662.06
A40: OK | B40: 45979 | C40: RECEBIMENTO | D40: TRANSFERENCIA MERCADO LIVRE | F40: 231.09 | G40: =G39+F40-E40 -> 20893.15
...

Sheet Dezembro
A1: FLUXO DE CAIXA DEZEMBRO/2025
A2: STATUS | B2: DATA | C2: TIPO | D2: HISTÓRICO | E2: DESPESA | F2: RECEITA | G2: SALDO
B3: SALDO INICIAL | G3: =Novembro!G69 -> 21114.84
A4: OK | B4: 45992 | C4: SHOPEE ADS | D4: SHOPEE ADS | E4: =30+20+20+30 -> 100 | G4: =G3+F4-E4 -> 21014.84
A5: OK | B5: 45992 | C5: RECEBIMENTO | D5: TRANSFERENCIA MERCADO LIVRE | F5: 839.36 | G5: =G4+F5-E5 -> 21854.2
A6: OK | B6: 45993 | C6: FORNECEDORES | D6: ETIQUETA TÉRMICA | E6: 208.9 | G6: =G5+F6-E6 -> 21645.3
A7: OK | B7: 45993 | C7: SHOPEE ADS | D7: SHOPEE ADS | E7: 20 | G7: =G6+F7-E7 -> 21625.3
A8: OK | B8: 45993 | C8: RECEBIMENTO | D8: TRANSFERENCIA SHOPEE | F8: 1492.93 | G8: =G7+F8-E8 -> 23118.23
A9: OK | B9: 45993 | C9: MATÉRIA PRIMA | D9: PAGAMENTO PEDIDO 02/11 - TUCK KIDS PARC 1/3 | E9: 338.33 | G9: =G8+F9-E9 -> 22779.9
A10: OK | B10: 45994 | C10: RECEBIMENTO | D10: TRANSFERENCIA MERCADO LIVRE | F10: 363.38 | G10: =G9+F10-E10 -> 23143.28
A11: OK | B11: 45995 | C11: RECEBIMENTO | D11: TRANSFERENCIA SHOPEE | F11: 1400 | G11: =G10+F11-E11 -> 24543.28
A12: OK | B12: 45995 | C12: MATÉRIA PRIMA | D12: PAGAMENTO PEDIDO 04/11 - TUCK KIDS PARC 1/3 | E12: 1108.33 | G12: =G11+F12-E12 -> 23434.95
A13: OK | B13: 45995 | C13: RECEBIMENTO | D13: TRANSFERENCIA MERCADO LIVRE | F13: 330.19 | G13: =G12+F13-E13 -> 23765.14
A14: OK | B14: 45996 | C14: RECEBIMENTO | D14: TRANSFERENCIA SHOPEE | F14: 1597.31 | G14: =G13+F14-E14 -> 25362.45
A15: OK | B15: 45996 | C15: MATÉRIA PRIMA | D15: PAGAMENTO PEDIDO 03/10 - TUCK KIDS PARC 2/3 | E15: 583.33 | G15: =G14+F15-E15 -> 24779.12
A16: OK | B16: 45996 | C16: MATÉRIA PRIMA | D16: PAGAMENTO PEDIDO 25/08 - TUCK KIDS PARC 3/3 | E16: 1417.5 | G16: =G15+F16-E16 -> 23361.62
A17: OK | B17: 45996 | C17: MATÉRIA PRIMA | D17: PAGAMENTO PEDIDO 05/09 - TUCK KIDS PARC 3/3 | E17: 531.66 | G17: =G16+F17-E17 -> 22829.96
A18: OK | B18: 45996 | C18: FORNECEDORES | D18: CONTABILIDADE | E18: 350 | G18: =G17+F18-E18 -> 22479.96
A19: OK | B19: 45996 | C19: FOLHA | D19: PAGAMENTO SALÁRIO BRUNA | E19: 1000 | G19: =G18+F19-E19 -> 21479.96
A20: OK | B20: 45997 | C20: RECEBIMENTO | D20: TRANSFERENCIA SHOPEE | F20: 1916.67 | G20: =G19+F20-E20 -> 23396.63
A21: OK | B21: 45998 | C21: RECEBIMENTO | D21: TRANSFERENCIA MERCADO LIVRE | F21: 866.95 | G21: =G20+F21-E21 -> 24263.58
A22: OK | B22: 45998 | C22: FORNECEDORES | D22: UPSELLER | E22: =149+45 -> 194 | G22: =G21+F22-E22 -> 24069.58
A23: OK | B23: 45998 | C23: MATÉRIA PRIMA | D23: PAGAMENTO PEDIDO 07/10 - TUCK KIDS PARC 2/3 | E23: 801.67 | G23: =G22+F23-E23 -> 23267.91
A24: OK | B24: 45999 | C24: RECEBIMENTO | D24: TRANSFERENCIA SHOPEE | F24: 2800 | G24: =G23+F24-E24 -> 26067.91
A25: OK | B25: 45999 | C25: RECEBIMENTO | D25: TRANSFERENCIA MERCADO LIVRE | F25: 798.42 | G25: =G24+F25-E25 -> 26866.33
A26: OK | B26: 45999 | C26: MATÉRIA PRIMA | D26: PAGAMENTO PEDIDO 10/10 - KAPPES PARC 3/4 | E26: 901.14 | G26: =G25+F26-E26 -> 25965.19
A27: OK | B27: 46000 | C27: FOLHA | D27: RESGATE VALOR SÓCIOS | E27: 9000 | G27: =G26+F27-E27 -> 16965.19
A28: OK | B28: 46000 | C28: MATÉRIA PRIMA | D28: PAGAMENTO PEDIDO 08/12 - KAPPES PARC 1/4 | E28: 1973.31 | G28: =G27+F28-E28 -> 14991.88
A29: OK | B29: 46000 | C29: RECEBIMENTO | D29: TRANSFERENCIA SHOPEE | F29: 2050 | G29: =G28+F29-E29 -> 17041.88
A30: OK | B30: 46000 | C30: RECEBIMENTO | D30: TRANSFERENCIA MERCADO LIVRE | F30: 726.97 | G30: =G29+F30-E30 -> 17768.85
A31: OK | B31: 46001 | C31: RECEBIMENTO | D31: TRANSFERENCIA SHOPEE | F31: 1501.44 | G31: =G30+F31-E31 -> 19270.29
A32: OK | B32: 46001 | C32: MATÉRIA PRIMA | D32: PAGAMENTO PEDIDO 10/11 - TUCK KIDS PARC 1/3 | E32: 2330 | G32: =G31+F32-E32 -> 16940.29
A33: OK | B33: 46001 | C33: APORTE | D33: APORTE JACKSON 2.246,82 | F33: 2246.82 | G33: =G32+F33-E33 -> 19187.11
A34: OK | B34: 46001 | C34: MATÉRIA PRIMA | D34: PAGAMENTO PEDIDO 16/09 - KAPPES | E34: 2246.82 | G34: =G33+F34-E34 -> 16940.29
A35: OK | B35: 46002 | C35: FORNECEDORES | D35: ENVELOPE DE SEGURANÇA | E35: 284.49 | G35: =G34+F35-E35 -> 16655.8
A36: OK | B36: 46002 | C36: RECEBIMENTO | D36: TRANSFERENCIA MERCADO LIVRE | F36: 1445.06 | G36: =G35+F36-E36 -> 18100.86
A37: OK | B37: 46003 | C37: RECEBIMENTO | D37: TRANSFERENCIA SHOPEE | F37: 3300 | G37: =G36+F37-E37 -> 21400.86
A38: OK | B38: 46003 | C38: MATÉRIA PRIMA | D38: PAGAMENTO PEDIDO 12/11 - TUCK KIDS PARC 1/3 | E38: 852 | G38: =G37+F38-E38 -> 20548.86
A39: OK | B39: 46003 | C39: FORNECEDORES | D39: ENVELOPE DE SEGURANÇA | E39: 150 | G39: =G38+F39-E39 -> 20398.86
A40: OK | B40: 46003 | C40: RECEBIMENTO | D40: TRANSFERENCIA MERCADO LIVRE | F40: 1056.74 | G40: =G39+F40-E40 -> 21455.6
...

Sheet Jan26
A1: FLUXO DE CAIXA JANEIRO/2026
A2: STATUS | B2: DATA | C2: TIPO | D2: HISTÓRICO | E2: DESPESA | F2: RECEITA | G2: SALDO
B3: SALDO INICIAL | G3: =Dezembro!G82 -> 37109.75
A4: OK | B4: 46023 | C4: RECEBIMENTO | D4: TRANSFERENCIA MERCADO LIVRE | F4: 4301.43 | G4: =G3+F4-E4 -> 41411.18
A5: OK | B5: 46023 | C5: MATÉRIA PRIMA | D5: PAGAMENTO PEDIDO 01/12 - TUCK KIDS PARC 1/3 | E5: 1901.5 | G5: =G4+F5-E5 -> 39509.68
A6: OK | B6: 46024 | C6: FORNECEDORES | D6: UPSELLER | E6: 45 | G6: =G5+F6-E6 -> 39464.68
A7: OK | B7: 46024 | C7: MATÉRIA PRIMA | D7: PAGAMENTO PEDIDO 02/11 - TUCK KIDS PARC 2/3 | E7: 338.33 | G7: =G6+F7-E7 -> 39126.35
A8: OK | B8: 46025 | C8: RECEBIMENTO | D8: TRANSFERENCIA MERCADO LIVRE | F8: 675.94 | G8: =G7+F8-E8 -> 39802.29
A9: OK | B9: 46025 | C9: RECEBIMENTO | D9: TRANSFERENCIA MERCADO LIVRE | F9: 959.42 | G9: =G8+F9-E9 -> 40761.71
A10: OK | B10: 46025 | C10: MATÉRIA PRIMA | D10: PAGAMENTO PEDIDO 03/10 - TUCK KIDS PARC 3/3 | E10: 583.34 | G10: =G9+F10-E10 -> 40178.37
A11: OK | B11: 46026 | C11: RECEBIMENTO | D11: TRANSFERENCIA MERCADO LIVRE | F11: 2277.03 | G11: =G10+F11-E11 -> 42455.4
A12: OK | B12: 46026 | C12: RECEBIMENTO | D12: TRANSFERENCIA SHOPEE | F12: 1461.26 | G12: =G11+F12-E12 -> 43916.66
A13: OK | B13: 46027 | C13: SHOPEE ADS | D13: SHOPEE ADS - SONHO MEU | E13: 70 | G13: =G12+F13-E13 -> 43846.66
A14: OK | B14: 46026 | C14: RECEBIMENTO | D14: TRANSFERENCIA MERCADO LIVRE | F14: 1482.1 | G14: =G13+F14-E14 -> 45328.76
A15: OK | B15: 46028 | C15: RECEBIMENTO | D15: TRANSFERENCIA MERCADO LIVRE | F15: 174.49 | G15: =G14+F15-E15 -> 45503.25
A16: OK | B16: 46029 | C16: FORNECEDORES | D16: UPSELLER | E16: 149 | G16: =G15+F16-E16 -> 45354.25
A17: OK | B17: 46028 | C17: RECEBIMENTO | D17: TRANSFERENCIA MERCADO LIVRE | F17: 1543.57 | G17: =G16+F17-E17 -> 46897.82
A18: OK | B18: 46028 | C18: RECEBIMENTO | D18: TRANSFERENCIA SHOPEE | F18: 1900 | G18: =G17+F18-E18 -> 48797.82
A19: OK | B19: 46029 | C19: MATÉRIA PRIMA | D19: PAGAMENTO PEDIDO 07/10 - TUCK KIDS PARC 3/3 | E19: 818.23 | G19: =G18+F19-E19 -> 47979.59
A20: OK | B20: 46029 | C20: FORNECEDORES | D20: CONTABILIDADE | E20: 350 | G20: =G19+F20-E20 -> 47629.59
A21: OK | B21: 46029 | C21: FOLHA | D21: PAGAMENTO SALÁRIO BRUNA | E21: 2000 | G21: =G20+F21-E21 -> 45629.59
A22: OK | B22: 46029 | C22: RECEBIMENTO | D22: TRANSFERENCIA MERCADO LIVRE | F22: 2896.93 | G22: =G21+F22-E22 -> 48526.52
A23: OK | B23: 46030 | C23: RECEBIMENTO | D23: TRANSFERENCIA SHOPEE | F23: 2418.04 | G23: =G22+F23-E23 -> 50944.56
A24: OK | B24: 46030 | C24: MATÉRIA PRIMA | D24: PAGAMENTO PEDIDO 10/10 - KAPPES PARC 4/4 | E24: 901.14 | G24: =G23+F24-E24 -> 50043.42
A25: OK | B25: 46031 | C25: RECEBIMENTO | D25: TRANSFERENCIA MERCADO LIVRE | F25: 1961.93 | G25: =G24+F25-E25 -> 52005.35
A26: OK | B26: 46030 | C26: RECEBIMENTO | D26: TRANSFERENCIA SHOPEE | F26: 1533.78 | G26: =G25+F26-E26 -> 53539.13
A27: OK | B27: 46030 | C27: SHOPEE ADS | D27: SHOPEE ADS - SONHO MEU | E27: 100 | G27: =G26+F27-E27 -> 53439.13
A28: OK | B28: 46032 | C28: SHOPEE ADS | D28: SHOPEE ADS - SONHO MEU | E28: 50 | G28: =G27+F28-E28 -> 53389.13
A29: OK | B29: 46031 | C29: MATÉRIA PRIMA | D29: PAGAMENTO PEDIDO 04/11 - TUCK KIDS PARC 2/3 | E29: 1108.33 | G29: =G28+F29-E29 -> 52280.8
A30: OK | B30: 46031 | C30: MATÉRIA PRIMA | D30: PAGAMENTO PEDIDO 08/12 - KAPPES PARC 2/4 | E30: 1973.31 | G30: =G29+F30-E30 -> 50307.49
A31: OK | B31: 46032 | C31: MATÉRIA PRIMA | D31: PAGAMENTO PEDIDO 10/11 - TUCK KIDS PARC 2/3 | E31: 2330 | G31: =G30+F31-E31 -> 47977.49
A32: OK | B32: 46032 | C32: MULTA | D32: MULTA ATRASO PAGAMENTOS | E32: 196.52 | G32: =G31+F32-E32 -> 47780.97
A33: OK | B33: 46032 | C33: APORTE | D33: APORTE JACKSON 2.246,82 | F33: 2246.82 | G33: =G32+F33-E33 -> 50027.79
A34: OK | B34: 46032 | C34: MATÉRIA PRIMA | D34: PAGAMENTO PEDIDO 16/09 - KAPPES | E34: 2246.82 | G34: =G33+F34-E34 -> 47780.97
A35: OK | B35: 46032 | C35: CARTAO | D35: CURSOS E TREINAMENTO PARC 4/12 | E35: 65.97 | G35: =G34+F35-E35 -> 47715
A36: OK | B36: 46033 | C36: RECEBIMENTO | D36: TRANSFERENCIA MERCADO LIVRE | F36: 2261 | G36: =G35+F36-E36 -> 49976
A37: OK | B37: 46034 | C37: RECEBIMENTO | D37: TRANSFERENCIA SHOPEE | F37: 3000 | G37: =G36+F37-E37 -> 52976
A38: OK | B38: 46034 | C38: MATÉRIA PRIMA | D38: PAGAMENTO PEDIDO 11/12 - TUCK KIDS PARC 1/3 | E38: 1641.67 | G38: =G37+F38-E38 -> 51334.33
A39: OK | B39: 46034 | C39: MATÉRIA PRIMA | D39: PAGAMENTO PEDIDO 12/11 - TUCK KIDS PARC 2/3 | E39: 869.32 | G39: =G38+F39-E39 -> 50465.01
A40: OK | B40: 46034 | C40: MATÉRIA PRIMA | D40: PAGAMENTO PEDIDO 12/01 - DAPPEN PARC 1/1 | E40: 4408.8 | G40: =G39+F40-E40 -> 46056.21
...

Sheet Fev26
A1: FLUXO DE CAIXA FEVEREIRO/2026
A2: STATUS | B2: DATA | C2: TIPO | D2: HISTÓRICO | E2: DESPESA | F2: RECEITA | G2: SALDO
B3: SALDO INICIAL | G3: ='Jan26'!G77 -> 33083.63
A4: OK | B4: 46055 | C4: MATÉRIA PRIMA | D4: PAGAMENTO PEDIDO 02/11 - TUCK KIDS PARC 3/3 | E4: 338.34 | G4: =G3+F4-E4 -> 32745.29
A5: OK | B5: 46055 | C5: RECEBIMENTO | D5: TRANSFERENCIA MERCADO LIVRE | F5: 2814.33 | G5: =G4+F5-E5 -> 35559.62
A6: OK | B6: 46055 | C6: FORNECEDORES | D6: GASOLINA MERCADORIA EM GASPAR | E6: 100 | G6: =G5+F6-E6 -> 35459.62
A7: OK | B7: 46055 | C7: RECEBIMENTO | D7: TRANSFERENCIA SHOPEE | F7: 2718.86 | G7: =G6+F7-E7 -> 38178.48
A8: OK | B8: 46056 | C8: RECEBIMENTO | D8: TRANSFERENCIA SHOPEE | F8: 2796.84 | G8: =G7+F8-E8 -> 40975.32
A9: OK | B9: 46057 | C9: RECEBIMENTO | D9: TRANSFERENCIA MERCADO LIVRE | F9: 1132.47 | G9: =G8+F9-E9 -> 42107.79
A10: OK | B10: 46058 | C10: RECEBIMENTO | D10: TRANSFERENCIA SHOPEE | F10: 2189.51 | G10: =G9+F10-E10 -> 44297.3
A11: OK | B11: 46058 | C11: MATÉRIA PRIMA | D11: PAGAMENTO PEDIDO PROG 26/12 - TUCK KIDS 1/3 | E11: 3861.66 | G11: =G10+F11-E11 -> 40435.64
A12: OK | B12: 46058 | C12: MATÉRIA PRIMA | D12: PAGAMENTO PEDIDO 02/01 - TUCK KIDS PARC 1/3 | E12: 5875 | G12: =G11+F12-E12 -> 34560.64
A13: OK | B13: 46059 | C13: MULTA | D13: MULTA ATRASO PAGAMENTOS | E13: =197.99+17.32 -> 215.31 | G13: =G12+F13-E13 -> 34345.33
A14: OK | B14: 46059 | C14: RECEBIMENTO | D14: TRANSFERENCIA MERCADO LIVRE | F14: 1328.77 | G14: =G13+F14-E14 -> 35674.1
A15: OK | B15: 46059 | C15: FORNECEDORES | D15: UPSELLER | E15: 149 | G15: =G14+F15-E15 -> 35525.1
A16: OK | B16: 46059 | C16: FORNECEDORES | D16: CONTABILIDADE | E16: 350 | G16: =G15+F16-E16 -> 35175.1
A17: OK | B17: 46059 | C17: FOLHA | D17: PAGAMENTO SALÁRIO BRUNA | E17: 2000 | G17: =G16+F17-E17 -> 33175.1
A18: OK | B18: 46059 | C18: MATÉRIA PRIMA | D18: PAGAMENTO PEDIDO 04/11 - TUCK KIDS PARC 3/3 | E18: 1108.34 | G18: =G17+F18-E18 -> 32066.76
A19: OK | B19: 46059 | C19: MATÉRIA PRIMA | D19: PAGAMENTO PEDIDO 08/12 - KAPPES PARC 3/4 | E19: 1973.31 | G19: =G18+F19-E19 -> 30093.45
A20: OK | B20: 46059 | C20: MATÉRIA PRIMA | D20: PAGAMENTO PEDIDO 10/11 - TUCK KIDS PARC 3/3 | E20: 2330 | G20: =G19+F20-E20 -> 27763.45
A21: OK | B21: 46060 | C21: RECEBIMENTO | D21: TRANSFERENCIA SHOPEE | F21: 1700 | G21: =G20+F21-E21 -> 29463.45
A22: OK | B22: 46060 | C22: RECEBIMENTO | D22: TRANSFERENCIA MERCADO LIVRE | F22: 1669.62 | G22: =G21+F22-E22 -> 31133.07
A23: OK | B23: 46061 | C23: TIKTOK ADS | D23: TIKTOK ADS - BÁSICO MAIS CRIATIVO | E23: 60 | G23: =G22+F23-E23 -> 31073.07
A24: OK | B24: 46062 | C24: RECEBIMENTO | D24: TRANSFERENCIA SHOPEE | F24: 1694.19 | G24: =G23+F24-E24 -> 32767.26
A25: OK | B25: 46062 | C25: FORNECEDORES | D25: EMBALAGEM MILHEIRO | E25: 158 | G25: =G24+F25-E25 -> 32609.26
A26: OK | B26: 46062 | C26: RECEBIMENTO | D26: TRANSFERENCIA MERCADO LIVRE | F26: 1344.84 | G26: =G25+F26-E26 -> 33954.1
A27: OK | B27: 46063 | C27: RECEBIMENTO | D27: TRANSFERENCIA SHOPEE | F27: 800 | G27: =G26+F27-E27 -> 34754.1
A28: OK | B28: 46065 | C28: CARTAO | D28: CURSOS E TREINAMENTO PARC 5/12 | E28: 64.42 | G28: =G27+F28-E28 -> 34689.68
A29: OK | B29: 46065 | C29: MATÉRIA PRIMA | D29: PAGAMENTO PEDIDO 12/01 - TUCK KIDS PARC 1/3 | E29: 4299.17 | G29: =G28+F29-E29 -> 30390.51
A30: OK | B30: 46065 | C30: MATÉRIA PRIMA | D30: PAGAMENTO PEDIDO 12/11 - TUCK KIDS PARC 3/3 | E30: 852 | G30: =G29+F30-E30 -> 29538.51
A31: OK | B31: 46065 | C31: RECEBIMENTO | D31: TRANSFERENCIA MERCADO LIVRE | F31: 2955.25 | G31: =G30+F31-E31 -> 32493.76
A32: OK | B32: 46066 | C32: RECEBIMENTO | D32: TRANSFERENCIA SHOPEE | F32: 1400 | G32: =G31+F32-E32 -> 33893.76
A33: OK | B33: 46066 | C33: TIKTOK ADS | D33: TIKTOK ADS - BÁSICO MAIS CRIATIVO | E33: 60 | G33: =G32+F33-E33 -> 33833.76
A34: OK | B34: 46067 | C34: RECEBIMENTO | D34: TRANSFERENCIA MERCADO LIVRE | F34: 1586.14 | G34: =G33+F34-E34 -> 35419.9
A35: AGENDADO | B35: 46066 | C35: MATÉRIA PRIMA | D35: PAGAMENTO PEDIDO 11/12 - TUCK KIDS PARC 2/3 | E35: 1641.67 | G35: =G34+F35-E35 -> 33778.23
A36: AGENDADO | B36: 46066 | C36: MATÉRIA PRIMA | D36: PAGAMENTO PEDIDO 04/12 - TUCK KIDS PARC 2/3 | E36: 386.66 | G36: =G35+F36-E36 -> 33391.57
A37: AGENDADO | B37: 46067 | C37: MATÉRIA PRIMA | D37: PAGAMENTO PEDIDO 14/11 - TUCK KIDS PARC 3/3 | E37: 2960 | G37: =G36+F37-E37 -> 30431.57
A38: AGENDADO | B38: 46068 | C38: MATÉRIA PRIMA | D38: PAGAMENTO PEDIDO 15/12 - TUCK KIDS PARC 2/3 | E38: 2658.33 | G38: =G37+F38-E38 -> 27773.24
B39: 46069 | C39: RECEBIMENTO | D39: TRANSFERENCIA SHOPEE | F39: 800 | G39: =G38+F39-E39 -> 28573.24
B40: 46069 | C40: RECEBIMENTO | D40: TRANSFERENCIA SHOPEE | F40: 1560 | G40: =G39+F40-E40 -> 30133.24
...

Sheet Mar26
A1: FLUXO DE CAIXA MARÇO/2026
A2: STATUS | B2: DATA | C2: TIPO | D2: HISTÓRICO | E2: DESPESA | F2: RECEITA | G2: SALDO
B3: SALDO INICIAL | G3: ='Fev26'!G51 -> 6168.44
B4: 46082 | C4: MATÉRIA PRIMA | D4: PAGAMENTO PEDIDO 01/12 - TUCK KIDS PARC 3/3 | E4: 1901.5 | G4: =G3+F4-E4 -> 4266.94
B5: 46082 | C5: MATÉRIA PRIMA | D5: PAGAMENTO PEDIDO 31/11 - TUCK KIDS 3/3 | E5: 670 | G5: =G4+F5-E5 -> 3596.94
B6: 46085 | C6: MATÉRIA PRIMA | D6: PAGAMENTO PEDIDO 04/12 - TUCK KIDS PARC 3/3 | E6: 386.66 | G6: =G5+F6-E6 -> 3210.28
B7: 46088 | C7: MATÉRIA PRIMA | D7: PAGAMENTO PEDIDO 02/01 - TUCK KIDS PARC 2/3 | E7: 5875 | G7: =G6+F7-E7 -> -2664.72
B8: 46088 | C8: MATÉRIA PRIMA | D8: PAGAMENTO PEDIDO 26/12 - TUCK KIDS PARC 2/3 | E8: 3861.67 | G8: =G7+F8-E8 -> -6526.39
B9: 46088 | C9: FORNECEDORES | D9: UPSELLER | E9: 149 | G9: =G8+F9-E9 -> -6675.39
B10: 46088 | C10: FORNECEDORES | D10: CONTABILIDADE | E10: 350 | G10: =G9+F10-E10 -> -7025.39
B11: 46088 | C11: FOLHA | D11: PAGAMENTO SALÁRIO BRUNA | E11: 2000 | G11: =G10+F11-E11 -> -9025.39
B12: 46091 | C12: MATÉRIA PRIMA | D12: PAGAMENTO PEDIDO PROG 15/01 - HEY KIDS 2/3 | E12: 11266.66 | G12: =G11+F12-E12 -> -20292.05
B13: 46091 | C13: MATÉRIA PRIMA | D13: PAGAMENTO PEDIDO 08/12 - KAPPES PARC 4/4 | E13: 1973.31 | G13: =G12+F13-E13 -> -22265.36
B14: 46091 | C14: APORTE | D14: APORTE JACKSON 2.246,82 | F14: 2246.82 | G14: =G13+F14-E14 -> -20018.54
B15: 46091 | C15: MATÉRIA PRIMA | D15: PAGAMENTO PEDIDO 16/09 - KAPPES | E15: 2246.82 | G15: =G14+F15-E15 -> -22265.36
B16: 46092 | C16: MATÉRIA PRIMA | D16: PAGAMENTO PEDIDO 11/12 - TUCK KIDS PARC 3/3 | E16: 1641.66 | G16: =G15+F16-E16 -> -23907.02
B17: 46093 | C17: MATÉRIA PRIMA | D17: PAGAMENTO PEDIDO 12/01 - TUCK KIDS PARC 2/3 | E17: 4299.16 | G17: =G16+F17-E17 -> -28206.18
B18: 46094 | C18: CARTAO | D18: CURSOS E TREINAMENTO PARC 6/12 | E18: 64.42 | G18: =G17+F18-E18 -> -28270.6
B19: 46096 | C19: MATÉRIA PRIMA | D19: PAGAMENTO PEDIDO 15/12 - TUCK KIDS PARC 3/3 | E19: 2658.33 | G19: =G18+F19-E19 -> -30928.93
B20: 46097 | C20: MATÉRIA PRIMA | D20: PAGAMENTO PEDIDO PROGRAMADO - TUCK KIDS PARC 3/3 | E20: 11100 | G20: =G19+F20-E20 -> -42028.93
B21: 46097 | C21: MATÉRIA PRIMA | D21: PAGAMENTO PEDIDO 16/12 - TUCK KIDS PARC 3/3 | E21: 1750 | G21: =G20+F21-E21 -> -43778.93
B22: 46100 | C22: MATÉRIA PRIMA | D22: PAGAMENTO PEDIDO 19/01 - TUCK KIDS PARC 2/3 | E22: 1140 | G22: =G21+F22-E22 -> -44918.93
B23: 46102 | C23: MATÉRIA PRIMA | D23: PAGAMENTO PEDIDO 19/01 - TUCK KIDS PARC 2/3 | E23: 1800 | G23: =G22+F23-E23 -> -46718.93
B24: 46109 | C24: MATÉRIA PRIMA | D24: PAGAMENTO PEDIDO 26/12 - TUCK KIDS 2/3 | E24: 2432 | G24: =G23+F24-E24 -> -49150.93
B25: 46109 | C25: MATÉRIA PRIMA | D25: PAGAMENTO PEDIDO PROG 20/01 - TUCK KIDS 2/3 | E25: 4188 | G25: =G24+F25-E25 -> -53338.93
B26: 46101 | C26: IMPOSTO | D26: IMPOSTO PROJETADO DE JANEIRO | E26: 0 | G26: =G25+F26-E26 -> -53338.93
E27: =SUM(E4:E26) -> 61754.19 | F27: =SUM(F9:F26) -> 2246.82 | G27: =G26 -> -53338.93

Sheet Abr26
A1: FLUXO DE CAIXA ABRIL/2026
A2: STATUS | B2: DATA | C2: TIPO | D2: HISTÓRICO | E2: DESPESA | F2: RECEITA | G2: SALDO
B3: SALDO INICIAL | G3: ='Mar26'!G27 -> -53338.93
B4: 46118 | C4: MATÉRIA PRIMA | D4: PAGAMENTO PEDIDO 26/12 - TUCK KIDS PARC 3/3 | E4: 3861.67 | G4: =G3+F4-E4 -> -57200.6
B5: 46118 | C5: MATÉRIA PRIMA | D5: PAGAMENTO PEDIDO 02/01 - TUCK KIDS PARC 3/3 | E5: 5875 | G5: =G4+F5-E5 -> -63075.6
B6: 46119 | C6: FORNECEDORES | D6: UPSELLER | E6: 149 | G6: =G5+F6-E6 -> -63224.6
B7: 46119 | C7: FORNECEDORES | D7: CONTABILIDADE | E7: 350 | G7: =G6+F7-E7 -> -63574.6
B8: 46119 | C8: FOLHA | D8: PAGAMENTO SALÁRIO BRUNA | E8: 2000 | G8: =G7+F8-E8 -> -65574.6
B9: 46122 | C9: MATÉRIA PRIMA | D9: PAGAMENTO PEDIDO PROG 15/01 - HEY KIDS 3/3 | E9: 11266.66 | G9: =G8+F9-E9 -> -76841.26
B10: 46124 | C10: MATÉRIA PRIMA | D10: PAGAMENTO PEDIDO 12/01 - TUCK KIDS PARC 3/3 | E10: 4299.16 | G10: =G9+F10-E10 -> -81140.42
B11: 46125 | C11: CARTAO | D11: CURSOS E TREINAMENTO PARC 7/12 | E11: 64.42 | G11: =G10+F11-E11 -> -81204.84
B12: 46131 | C12: MATÉRIA PRIMA | D12: PAGAMENTO PEDIDO 19/01 - TUCK KIDS PARC 3/3 | E12: 1140 | G12: =G11+F12-E12 -> -82344.84
B13: 46132 | C13: MATÉRIA PRIMA | D13: PAGAMENTO PEDIDO 19/01 - TUCK KIDS PARC 3/3 | E13: 1800 | G13: =G12+F13-E13 -> -84144.84
B14: 46139 | C14: MATÉRIA PRIMA | D14: PAGAMENTO PEDIDO 26/12 - TUCK KIDS 3/3 | E14: 2432 | G14: =G13+F14-E14 -> -86576.84
B15: 46139 | C15: MATÉRIA PRIMA | D15: PAGAMENTO PEDIDO 20/01 - TUCK KIDS PARC 3/3 | E15: 4188 | G15: =G14+F15-E15 -> -90764.84
B16: 46132 | C16: IMPOSTO | D16: IMPOSTO PROJETADO DE ABRIL | E16: 0 | G16: =G15+F16-E16 -> -90764.84
E17: =SUM(E4:E16) -> 37425.91 | F17: =SUM(F6:F16) -> 0 | G17: =G16 -> -90764.84
